Workbook

Sheet Sheet1
A1: Student ID | B1: Last Name | C1: First Name | D1: Sex | E1: Grade | F1: Course title | G1: Mark2 | H1: Citizenship | I1: LangFlu | J1: Has 504 | K1: Has IEP | L1: Interventions | O1: Student ID | P1: First Name | Q1: Last Name | R1: LangFlu | S1: Effective Date | T1: has 504 | U1: Has dis | V1: Disability
A2: 47414 | B2: Ajiataz Maldonado | C2: Edward | D2: M | E2: 6 | F2: Social St. 6 | G2: D | H2: S | I2: R | J2: =IFERROR(VLOOKUP(A2, Sheet1!$O$1:$V$156, 6, FALSE), "") | K2: =IFERROR(VLOOKUP(A2, Sheet1!$O$1:$V$156, 7, FALSE), "") | O2: 47490 | P2: Grace | Q2: Heidenberg | R2: E | T2: =IF(S2=""," ","Y") | U2: =IF(V2=""," ","Y") -> Y | V2: 210
A3: 47414 | B3: Ajiataz Maldonado | C3: Edward | D3: M | E3: 6 | F3: CC Math 6 | G3: F | H3: S | I3: R | J3: =IFERROR(VLOOKUP(A3, Sheet1!$O$1:$V$156, 6, FALSE), "") | K3: =IFERROR(VLOOKUP(A3, Sheet1!$O$1:$V$156, 7, FALSE), "") | O3: 45149 | P3: Valentina | Q3: Vasquez | R3: F | T3: =IF(S3=""," ","Y") | U3: =IF(V3=""," ","Y") -> Y | V3: 220
A4: 44761 | B4: Alfieri | C4: Joseph | D4: M | E4: 6 | F4: Social St. 6 | G4: B- | H4: N | I4: E | J4: =IFERROR(VLOOKUP(A4, Sheet1!$O$1:$V$156, 6, FALSE), "") -> Y | K4: =IFERROR(VLOOKUP(A4, Sheet1!$O$1:$V$156, 7, FALSE), "") | O4: 44908 | P4: Riley | Q4: Loberman | R4: E | S4: 01/24/2025 | T4: =IF(S4=""," ","Y") -> Y | U4: =IF(V4=""," ","Y") -> Y | V4: 240
A5: 46820 | B5: Allen | C5: Owen | D5: M | E5: 8 | F5: Cross Training | G5: C- | H5: U | I5: E | J5: =IFERROR(VLOOKUP(A5, Sheet1!$O$1:$V$156, 6, FALSE), "") -> Y | K5: =IFERROR(VLOOKUP(A5, Sheet1!$O$1:$V$156, 7, FALSE), "") | O5: 44932 | P5: Cameron | Q5: Maida | R5: E | S5: 08/19/2025 | T5: =IF(S5=""," ","Y") -> Y | U5: =IF(V5=""," ","Y") -> Y | V5: 240
A6: 46820 | B6: Allen | C6: Owen | D6: M | E6: 8 | F6: Science 8 | G6: F | H6: S | I6: E | J6: =IFERROR(VLOOKUP(A6, Sheet1!$O$1:$V$156, 6, FALSE), "") -> Y | K6: =IFERROR(VLOOKUP(A6, Sheet1!$O$1:$V$156, 7, FALSE), "") | O6: 44887 | P6: Declan | Q6: O'Brien | R6: E | S6: 02/05/2025 | T6: =IF(S6=""," ","Y") -> Y | U6: =IF(V6=""," ","Y") -> Y | V6: 240
A7: 46820 | B7: Allen | C7: Owen | D7: M | E7: 8 | F7: Art | G7: F | H7: N | I7: E | J7: =IFERROR(VLOOKUP(A7, Sheet1!$O$1:$V$156, 6, FALSE), "") -> Y | K7: =IFERROR(VLOOKUP(A7, Sheet1!$O$1:$V$156, 7, FALSE), "") | O7: 44820 | P7: Aysa | Q7: Rogers | R7: E | S7: 09/15/2025 | T7: =IF(S7=""," ","Y") -> Y | U7: =IF(V7=""," ","Y") -> Y | V7: 240
A8: 46820 | B8: Allen | C8: Owen | D8: M | E8: 8 | F8: Lang Arts 8 | G8: D- | H8: U | I8: E | J8: =IFERROR(VLOOKUP(A8, Sheet1!$O$1:$V$156, 6, FALSE), "") -> Y | K8: =IFERROR(VLOOKUP(A8, Sheet1!$O$1:$V$156, 7, FALSE), "") | O8: 44296 | P8: Elle | Q8: Stout | R8: E | S8: 05/27/2025 | T8: =IF(S8=""," ","Y") -> Y | U8: =IF(V8=""," ","Y") -> Y | V8: 240
A9: 46820 | B9: Allen | C9: Owen | D9: M | E9: 8 | F9: CC Math 8 | G9: F | H9: S | I9: E | J9: =IFERROR(VLOOKUP(A9, Sheet1!$O$1:$V$156, 6, FALSE), "") -> Y | K9: =IFERROR(VLOOKUP(A9, Sheet1!$O$1:$V$156, 7, FALSE), "") | O9: 43889 | P9: Brayden | Q9: Tindall | R9: E | S9: 05/25/2022 | T9: =IF(S9=""," ","Y") -> Y | U9: =IF(V9=""," ","Y") -> Y | V9: 240
A10: 47473 | B10: Alvarado | C10: Eric | D10: M | E10: 8 | F10: Science 8 | G10: F | H10: S | I10: E | J10: =IFERROR(VLOOKUP(A10, Sheet1!$O$1:$V$156, 6, FALSE), "") | K10: =IFERROR(VLOOKUP(A10, Sheet1!$O$1:$V$156, 7, FALSE), "") | O10: 45258 | P10: Spencer | Q10: Barash | R10: E | T10: =IF(S10=""," ","Y") | U10: =IF(V10=""," ","Y") -> Y | V10: 240
A11: 47473 | B11: Alvarado | C11: Eric | D11: M | E11: 8 | F11: PE 7/8 | G11: C- | H11: U | I11: E | J11: =IFERROR(VLOOKUP(A11, Sheet1!$O$1:$V$156, 6, FALSE), "") | K11: =IFERROR(VLOOKUP(A11, Sheet1!$O$1:$V$156, 7, FALSE), "") | O11: 44421 | P11: Callen | Q11: Kirkland | R11: E | S11: 09/20/2024 | T11: =IF(S11=""," ","Y") -> Y | U11: =IF(V11=""," ","Y") -> Y | V11: 240
A12: 47473 | B12: Alvarado | C12: Eric | D12: M | E12: 8 | F12: Lang Arts 8 | G12: F | H12: S | I12: E | J12: =IFERROR(VLOOKUP(A12, Sheet1!$O$1:$V$156, 6, FALSE), "") | K12: =IFERROR(VLOOKUP(A12, Sheet1!$O$1:$V$156, 7, FALSE), "") | O12: 45263 | P12: Lila | Q12: Kleinman-Green | R12: E | S12: 10/02/2024 | T12: =IF(S12=""," ","Y") -> Y | U12: =IF(V12=""," ","Y") -> Y | V12: 240
A13: 47473 | B13: Alvarado | C13: Eric | D13: M | E13: 8 | F13: CC Math 8 | G13: F | H13: S | I13: E | J13: =IFERROR(VLOOKUP(A13, Sheet1!$O$1:$V$156, 6, FALSE), "") | K13: =IFERROR(VLOOKUP(A13, Sheet1!$O$1:$V$156, 7, FALSE), "") | O13: 45235 | P13: Forrest | Q13: Morales | R13: E | S13: 10/21/2025 | T13: =IF(S13=""," ","Y") -> Y | U13: =IF(V13=""," ","Y") -> Y | V13: 240
A14: 46847 | B14: Alvarez | C14: Adam | D14: M | E14: 8 | F14: CC Math 8 | G14: F | H14: S | I14: E | J14: =IFERROR(VLOOKUP(A14, Sheet1!$O$1:$V$156, 6, FALSE), "") | K14: =IFERROR(VLOOKUP(A14, Sheet1!$O$1:$V$156, 7, FALSE), "") | O14: 45334 | P14: Davi Luis | Q14: Batista | R14: R | T14: =IF(S14=""," ","Y") | U14: =IF(V14=""," ","Y") -> Y | V14: 240
A15: 45106 | B15: Atnip | C15: Luke | D15: M | E15: 6 | F15: Lang Arts 6 | G15: A- | H15: N | I15: E | J15: =IFERROR(VLOOKUP(A15, Sheet1!$O$1:$V$156, 6, FALSE), "") -> Y | K15: =IFERROR(VLOOKUP(A15, Sheet1!$O$1:$V$156, 7, FALSE), "") | O15: 44284 | P15: Sophia | Q15: Becker | R15: E | T15: =IF(S15=""," ","Y") | U15: =IF(V15=""," ","Y") -> Y | V15: 240
A16: 44720 | B16: Bakerink | C16: Cedrick | D16: M | E16: 7 | F16: Spanish 1A | G16: D+ | H16: S | I16: E | J16: =IFERROR(VLOOKUP(A16, Sheet1!$O$1:$V$156, 6, FALSE), "") | K16: =IFERROR(VLOOKUP(A16, Sheet1!$O$1:$V$156, 7, FALSE), "") | O16: 45000 | P16: Ava | Q16: Bradley | R16: E | T16: =IF(S16=""," ","Y") | U16: =IF(V16=""," ","Y") -> Y | V16: 240
A17: 44720 | B17: Bakerink | C17: Cedrick | D17: M | E17: 7 | F17: Social St. 7 | G17: D | H17: S | I17: E | J17: =IFERROR(VLOOKUP(A17, Sheet1!$O$1:$V$156, 6, FALSE), "") | K17: =IFERROR(VLOOKUP(A17, Sheet1!$O$1:$V$156, 7, FALSE), "") | O17: 44763 | P17: Caleb | Q17: Chuc Ojeda | R17: F | T17: =IF(S17=""," ","Y") | U17: =IF(V17=""," ","Y") -> Y | V17: 240
A18: 44720 | B18: Bakerink | C18: Cedrick | D18: M | E18: 7 | F18: Cross Training | G18: C+ | H18: N | I18: E | J18: =IFERROR(VLOOKUP(A18, Sheet1!$O$1:$V$156, 6, FALSE), "") | K18: =IFERROR(VLOOKUP(A18, Sheet1!$O$1:$V$156, 7, FALSE), "") | O18: 44956 | P18: Aaliyah | Q18: Cross-Nice | R18: E | T18: =IF(S18=""," ","Y") | U18: =IF(V18=""," ","Y") -> Y | V18: 240
A19: 47149 | B19: Balladares | C19: Melody | D19: F | E19: 7 | F19: Cross Training | G19: C+ | H19: N | I19: E | J19: =IFERROR(VLOOKUP(A19, Sheet1!$O$1:$V$156, 6, FALSE), "") | K19: =IFERROR(VLOOKUP(A19, Sheet1!$O$1:$V$156, 7, FALSE), "") | O19: 44828 | P19: Kendall | Q19: Dowd | R19: E | T19: =IF(S19=""," ","Y") | U19: =IF(V19=""," ","Y") -> Y | V19: 240
A20: 45162 | B20: Ballard | C20: Greyson | D20: M | E20: 6 | F20: Science 6 | G20: D | H20: S | I20: E | J20: =IFERROR(VLOOKUP(A20, Sheet1!$O$1:$V$156, 6, FALSE), "") | K20: =IFERROR(VLOOKUP(A20, Sheet1!$O$1:$V$156, 7, FALSE), "") -> Y | O20: 44886 | P20: Henry | Q20: Duncan | R20: E | T20: =IF(S20=""," ","Y") | U20: =IF(V20=""," ","Y") -> Y | V20: 240
A21: 47215 | B21: Bivins | C21: Iry'una | D21: F | E21: 6 | F21: PE 6B | G21: B | H21: N | I21: E | J21: =IFERROR(VLOOKUP(A21, Sheet1!$O$1:$V$156, 6, FALSE), "") | K21: =IFERROR(VLOOKUP(A21, Sheet1!$O$1:$V$156, 7, FALSE), "") | O21: 44482 | P21: Micah | Q21: Fells | R21: E | T21: =IF(S21=""," ","Y") | U21: =IF(V21=""," ","Y") -> Y | V21: 240
A22: 45319 | B22: Busch | C22: Benjamin | D22: M | E22: 7 | F22: Cross Training | G22: B+ | H22: N | I22: E | J22: =IFERROR(VLOOKUP(A22, Sheet1!$O$1:$V$156, 6, FALSE), "") | K22: =IFERROR(VLOOKUP(A22, Sheet1!$O$1:$V$156, 7, FALSE), "") | O22: 45210 | P22: Dillon | Q22: Fischer | R22: E | T22: =IF(S22=""," ","Y") | U22: =IF(V22=""," ","Y") -> Y | V22: 240
A23: 47179 | B23: Calderon Alvarez | C23: Braily | D23: M | E23: 8 | F23: Algebra 1 | G23: D | H23: S | I23: E | J23: =IFERROR(VLOOKUP(A23, Sheet1!$O$1:$V$156, 6, FALSE), "") | K23: =IFERROR(VLOOKUP(A23, Sheet1!$O$1:$V$156, 7, FALSE), "") | O23: 44702 | P23: Vincent | Q23: Fong | R23: E | T23: =IF(S23=""," ","Y") | U23: =IF(V23=""," ","Y") -> Y | V23: 240
A24: 46851 | B24: Casas | C24: Daisey | D24: F | E24: 8 | F24: Social St. 8 | G24: F | H24: N | I24: L | J24: =IFERROR(VLOOKUP(A24, Sheet1!$O$1:$V$156, 6, FALSE), "") | K24: =IFERROR(VLOOKUP(A24, Sheet1!$O$1:$V$156, 7, FALSE), "") | O24: 43915 | P24: Cash | Q24: Gianinno | R24: E | T24: =IF(S24=""," ","Y") | U24: =IF(V24=""," ","Y") -> Y | V24: 240
A25: 46851 | B25: Casas | C25: Daisey | D25: F | E25: 8 | F25: Science 8 | G25: D+ | H25: S | I25: L | J25: =IFERROR(VLOOKUP(A25, Sheet1!$O$1:$V$156, 6, FALSE), "") | K25: =IFERROR(VLOOKUP(A25, Sheet1!$O$1:$V$156, 7, FALSE), "") | O25: 44408 | P25: Elena | Q25: Hernandez Mazariegos | R25: L | T25: =IF(S25=""," ","Y") | U25: =IF(V25=""," ","Y") -> Y | V25: 240
... A59: 44863 | B59: Gonzalez Vazquez | C59: Andres | D59: M | E59: 7 | F59: Social St. 7 | G59: F | H59: S | I59: R | J59: =IFERROR(VLOOKUP(A59, Sheet1!$O$1:$V$156, 6, FALSE), "") | K59: =IFERROR(VLOOKUP(A59, Sheet1!$O$1:$V$156, 7, FALSE), "") -> Y | O59: 45194 | P59: Maya | Q59: Gasper | R59: E | T59: =IF(S59=""," ","Y") | U59: =IF(V59=""," ","Y") -> Y | V59: 260
A60: 44863 | B60: Gonzalez Vazquez | C60: Andres | D60: M | E60: 7 | F60: CC Math 7 | G60: F | H60: N | I60: R | J60: =IFERROR(VLOOKUP(A60, Sheet1!$O$1:$V$156, 6, FALSE), "") | K60: =IFERROR(VLOOKUP(A60, Sheet1!$O$1:$V$156, 7, FALSE), "") -> Y | O60: 46020 | P60: Adelaide | Q60: O'Connor | R60: E | S60: 05/20/2024 | T60: =IF(S60=""," ","Y") -> Y | U60: =IF(V60=""," ","Y") -> Y | V60: 280
A61: 44863 | B61: Gonzalez Vazquez | C61: Andres | D61: M | E61: 7 | F61: Science 7 | G61: D+ | H61: S | I61: R | J61: =IFERROR(VLOOKUP(A61, Sheet1!$O$1:$V$156, 6, FALSE), "") | K61: =IFERROR(VLOOKUP(A61, Sheet1!$O$1:$V$156, 7, FALSE), "") -> Y | O61: 44567 | P61: Samuel | Q61: Pavlov | R61: R | S61: 04/22/2024 | T61: =IF(S61=""," ","Y") -> Y | U61: =IF(V61=""," ","Y") -> Y | V61: 260
A62: 44863 | B62: Gonzalez Vazquez | C62: Andres | D62: M | E62: 7 | F62: Applied Science | G62: F | H62: S | I62: R | J62: =IFERROR(VLOOKUP(A62, Sheet1!$O$1:$V$156, 6, FALSE), "") | K62: =IFERROR(VLOOKUP(A62, Sheet1!$O$1:$V$156, 7, FALSE), "") -> Y | O62: 45245 | P62: Cole | Q62: Zargar | R62: E | T62: =IF(S62=""," ","Y") | U62: =IF(V62=""," ","Y") -> Y | V62: 240
A63: 47409 | B63: Gramajo Rodas | C63: Alexandra | D63: F | E63: 6 | F63: CC Math 6 | G63: F | H63: S | I63: L | J63: =IFERROR(VLOOKUP(A63, Sheet1!$O$1:$V$156, 6, FALSE), "") | K63: =IFERROR(VLOOKUP(A63, Sheet1!$O$1:$V$156, 7, FALSE), "") | O63: 44357 | P63: James | Q63: Kelly | R63: E | S63: 08/21/2023 | T63: =IF(S63=""," ","Y") -> Y | U63: =IF(V63=""," ","Y") -> Y | V63: 280
A64: 44366 | B64: Harbidge | C64: Shea | D64: F | E64: 8 | F64: CC Math 8 | G64: D+ | H64: S | I64: E | J64: =IFERROR(VLOOKUP(A64, Sheet1!$O$1:$V$156, 6, FALSE), "") | K64: =IFERROR(VLOOKUP(A64, Sheet1!$O$1:$V$156, 7, FALSE), "") | O64: 45278 | P64: Miles | Q64: Trenary | R64: E | S64: 10/15/2025 | T64: =IF(S64=""," ","Y") -> Y | U64: =IF(V64=""," ","Y") -> Y | V64: 280
A65: 44380 | B65: Hayden | C65: Robert | D65: M | E65: 8 | F65: CC Math 8 | G65: F | H65: S | I65: R | J65: =IFERROR(VLOOKUP(A65, Sheet1!$O$1:$V$156, 6, FALSE), "") | K65: =IFERROR(VLOOKUP(A65, Sheet1!$O$1:$V$156, 7, FALSE), "") | O65: 46001 | P65: Evan | Q65: Aronson | R65: E | T65: =IF(S65=""," ","Y") | U65: =IF(V65=""," ","Y") -> Y | V65: 280
A66: 44380 | B66: Hayden | C66: Robert | D66: M | E66: 8 | F66: Science 8 | G66: C+ | H66: N | I66: R | J66: =IFERROR(VLOOKUP(A66, Sheet1!$O$1:$V$156, 6, FALSE), "") | K66: =IFERROR(VLOOKUP(A66, Sheet1!$O$1:$V$156, 7, FALSE), "") | O66: 47059 | P66: Zamir | Q66: Coleman | R66: E | T66: =IF(S66=""," ","Y") | U66: =IF(V66=""," ","Y") -> Y | V66: 280
A67: 45002 | B67: Hernandez | C67: Alexander Aaron | D67: M | E67: 7 | F67: Cross Training | G67: B+ | H67: N | I67: F | J67: =IFERROR(VLOOKUP(A67, Sheet1!$O$1:$V$156, 6, FALSE), "") | K67: =IFERROR(VLOOKUP(A67, Sheet1!$O$1:$V$156, 7, FALSE), "") | O67: 45723 | P67: Henry | Q67: Coupar | R67: E | T67: =IF(S67=""," ","Y") | U67: =IF(V67=""," ","Y") -> Y | V67: 280
A68: 46850 | B68: Hernandez-Velasquez | C68: Marvin | D68: M | E68: 8 | F68: ELD 1 | G68: B+ | H68: N | I68: L | J68: =IFERROR(VLOOKUP(A68, Sheet1!$O$1:$V$156, 6, FALSE), "") | K68: =IFERROR(VLOOKUP(A68, Sheet1!$O$1:$V$156, 7, FALSE), "") | O68: 44870 | P68: Matthew | Q68: DeMartini | R68: E | T68: =IF(S68=""," ","Y") | U68: =IF(V68=""," ","Y") -> Y | V68: 280
A69: 44868 | B69: Houssain | C69: Zakareya | D69: M | E69: 7 | F69: Cross Training | G69: C | H69: N | I69: R | J69: =IFERROR(VLOOKUP(A69, Sheet1!$O$1:$V$156, 6, FALSE), "") | K69: =IFERROR(VLOOKUP(A69, Sheet1!$O$1:$V$156, 7, FALSE), "") | O69: 46015 | P69: Jeffrey | Q69: Diaz | R69: E | T69: =IF(S69=""," ","Y") | U69: =IF(V69=""," ","Y") -> Y | V69: 280
A70: 44868 | B70: Houssain | C70: Zakareya | D70: M | E70: 7 | F70: CC Math 7 | G70: D- | H70: N | I70: R | J70: =IFERROR(VLOOKUP(A70, Sheet1!$O$1:$V$156, 6, FALSE), "") | K70: =IFERROR(VLOOKUP(A70, Sheet1!$O$1:$V$156, 7, FALSE), "") | O70: 44753 | P70: Henry | Q70: Erickson | R70: E | T70: =IF(S70=""," ","Y") | U70: =IF(V70=""," ","Y") -> Y | V70: 280
A71: 44868 | B71: Houssain | C71: Zakareya | D71: M | E71: 7 | F71: Lang Arts 7 | G71: F | H71: S | I71: R | J71: =IFERROR(VLOOKUP(A71, Sheet1!$O$1:$V$156, 6, FALSE), "") | K71: =IFERROR(VLOOKUP(A71, Sheet1!$O$1:$V$156, 7, FALSE), "") | O71: 43923 | P71: Griffin | Q71: Feist | R71: E | T71: =IF(S71=""," ","Y") | U71: =IF(V71=""," ","Y") -> Y | V71: 280
A72: 47126 | B72: Hudson | C72: Sophia | D72: F | E72: 6 | F72: CC Math 6 | G72: F | H72: S | I72: E | J72: =IFERROR(VLOOKUP(A72, Sheet1!$O$1:$V$156, 6, FALSE), "") | K72: =IFERROR(VLOOKUP(A72, Sheet1!$O$1:$V$156, 7, FALSE), "") | O72: 45347 | P72: Adam | Q72: Immoos | R72: E | T72: =IF(S72=""," ","Y") | U72: =IF(V72=""," ","Y") -> Y | V72: 280
A73: 45347 | B73: Immoos | C73: Adam | D73: M | E73: 8 | F73: Social St. 8 | G73: F | H73: S | I73: E | J73: =IFERROR(VLOOKUP(A73, Sheet1!$O$1:$V$156, 6, FALSE), "") | K73: =IFERROR(VLOOKUP(A73, Sheet1!$O$1:$V$156, 7, FALSE), "") -> Y | O73: 44457 | P73: Johann | Q73: Konis Clemmer | R73: E | T73: =IF(S73=""," ","Y") | U73: =IF(V73=""," ","Y") -> Y | V73: 280
...
